Workbook

Sheet readme
A1: axis | B1: code | C1: description
A2: topic | B2: CRIMINAL_LAW | C2: Conduct that can lead to prosecution or punishment by the state: police, arrest, investigations, charges, criminal defense, sentencing, probation, penalties, victims' rights, criminal procedure, traffic and drug offenses, fraud, and hacking/phishing/malware/DDoS as offenses.
A3: topic | B3: IMMIGRATION_AND_CITIZENSHIP | C3: A person's right to enter, remain in, or belong to a country: visas, work authorization, residence permits, asylum, refugee status, citizenship, naturalization, deportation or removal, family-based migration.
A4: topic | B4: FAMILY_AND_ESTATES | C4: Family relationships and succession of personal assets: marriage, divorce, custody, child/spousal support, adoption, guardianship, domestic violence, parentage; wills, trusts, probate, estates, inheritance, executors, succession.
A5: topic | B5: EMPLOYMENT_AND_LABOR | C5: The user as a worker or an employer's duties to workers: employment contracts, wages, dismissal, workplace discrimination and harassment, leave, workplace safety, severance, unions, worker-vs-contractor status, workers' compensation.
A6: topic | B6: HOUSING_AND_PROPERTY | C6: Where the user lives and real property they own or occupy: rent, eviction, landlord-tenant, deposits, habitability, mortgages, foreclosure, neighbors, ownership, conveyancing, easements, zoning, land use, building permits, adverse possession.
A7: topic | B7: INTELLECTUAL_PROPERTY | C7: Ownership and use of creative, technical, and brand assets: copyright, trademark, patent, trade secrets, licensing, infringement, and ownership of creative or technical work.
A8: topic | B8: DATA_PRIVACY_AND_TECHNOLOGY | C8: Personal data and the law governing online platforms and technology: data-protection/privacy rights, consent, data deletion, surveillance, marketing privacy, platform data practices, content moderation, intermediary/platform liability, lawful data scraping, and technology/AI regulation.
A9: topic | B9: CIVIL_RIGHTS_AND_CONSTITUTIONAL | C9: Fundamental rights and the powers/limits of government: discrimination outside employment and housing, free speech, due process, equal protection, privacy as a constitutional right, human-rights claims, constitutional interpretation, separation of powers, judicial review, government powers.
A10: topic | B10: TORTS_AND_CIVIL_LIABILITY | C10: Being harmed by, or liable to, another party outside a contract: personal injury, negligence, professional malpractice, defamation, product liability, nuisance, wrongful death, emotional distress, and civil damages claims.
A11: topic | B11: TAX_LAW | C11: Personal and business taxation: income, corporate, payroll, property, sales, VAT, capital-gains, and international tax; tax returns, deductions, audits, planning, compliance, liability, and disputes with tax or revenue authorities.
A12: topic | B12: BUSINESS_AND_COMMERCIAL | C12: Running, forming, or dealing with a business or entity: company formation and governance, shareholder/partner matters, self-employment as a business, B2B and commercial contracts, generic civil agreements, commercial compliance, and licensing.
... A26: user_context | B26: CREATIVE_FICTION | C26: Fiction, roleplay, worldbuilding, or invented scenarios (e.g. drafting a statute for a fictional country).

Sheet Jerry
A1: id | B1: seeks_legal_guidance | C1: contains_legal_content | D1: personalized_or_operational | E1: user_context | F1: primary_topic | G1: topics | H1: primary_request_type | I1: request_types | J1: requests_legal_drafting | K1: first_guidance_user_turn_id | L1: first_drafting_user_turn_id | M1: relevant_user_turn_ids | N1: uncertainty | O1: short_rationale | P1: num_turns | Q1: conversation | R1: reviewer_correct_classification | S1: reviewer_verdict_topic | T1: reviewer_notes
A2: 5632d11d95fe65ebfd896a6bdb07a762 | B2: FALSE | C2: FALSE | D2: FALSE | E2: CREATIVE_FICTION | J2: FALSE | N2: low | O2: The user requests a fictional character-fusion description and does not discuss any legal issue or seek legal guidance. | P2: 2 | Q2: [turn 0, user] Ash Ketchum (Pokémon) (casual shorts) and Serena (Pokémon) (casual shorts) fusion; complete in-depth description of name, attire, personality, fusion process (from beginning to end), techniques, and abilities; extremely detailed overview of combined hermaphroditic physique from head to toe [turn 1, assistant] Name: Ashrena Ketsuna Attire: Ashrena's attire is a combination of Ash Ketchum's and Serena's casual outfits. They wear a light blue, short-sleeved jacket similar to Ash's, with a red and white trim along the collar and cuffs. Underneath, they wear a white polo shirt. Their shorts are black with blue trim, resembling Serena's shorts. They also wear a pair of fingerless gloves and ankle-high black boots. Ashrena completes their outfit with a black hat turned backward, similar to Ash's iconic cap. Personality: Ashrena is an adventurous and determined individual, inheriting Ash's passion for Pokémon training and Serena's elegance and grace. They have a strong sense of justice and are quick to defend others if they feel they're being mistreated. Ashrena's fusion has also amplified their curiosity and desire to explore the Pokémon world. They have a friendly and charismatic nature, often motivating others with their positive attitude. Fusion Process: The fusion process begins with Ash and Serena standing together in a calm environment, their minds focused on achieving a strong bond. They then join hands, their palms glowing with a mix of orange and pink energy. As the energy envelops them, their bodies fuse together, taking the best features and characteristics from each. The fusion process is seamless and filled with a warm, comforting feeling, signifying the birth of Ashrena Ketsuna. Techniques and Abilities: 1. Pikachu's Electric Bolt: Ashrena can utilize Pikachu's signature move, generating powerful electric bolts that can paralyze and damage opponents. 2. Braixen's Fire Spin: Ashrena can conjure swirling flames around them, creating a vortex of fire that traps and weakens adversaries. 3. Greninja's Water Shuriken: Possessing the water ninja's abilities, Ashrena can form sharp water projectiles and hurl them swiftly towards enemies, breaking through defenses. 4. Pancham's Superpower: Ashrena channels Pancham's strength, enhancing their physical abilities momentarily. This allows them to deliver powerful punches and kicks, even breaking through barriers. 5. Sylveon's Fairy Wind: Drawing upon Serena's bond with Sylveon, Ashrena releases soothing, yet powerful winds imbued with fairy energy to heal wounds and calm aggressive foes. 6. Lucario's Aura Sphere: Ashrena taps into Lucario's aura powers, creating a powerful sphere of energy that can be launched at opponents, dealing significant damage. Physique Description: Head: Ashrena has a head that combines features from both Ash and Serena. They have Ash's messy, jet-black hair with Serena's silky, shoulder-length hair. Their eyes are a striking shade of blue-green, holding an intense determination with a touch of elegance. Ashrena's face is a perfect blend of masculine and feminine, possessing Ash's strong jawline while still exuding Serena's softness. Body: Ashrena's body embodies a balanced blend of Ash's athleticism and Serena's grace. They possess a toned and agile build, muscular but still retaining a slender shape. The fusion process has given Ashrena a hermaphroditic physique, combining both masculine and feminine attributes. Torso: Their torso is defined by well-developed chest muscles, but it maintains a graceful curve, reflecting Serena's elegance. Ashrena has a straight posture, exuding confidence and purpose. Limbs: Ashrena's arms and legs are muscular, displaying the athleticism inherited from Ash. However, they retain Serena's smoothness and gracefulness. The arms are strong, allowing for precise and powerful strikes. The legs are toned, granting agility and speed. Overall, Ashrena Ketsuna is a remarkable fusion of Ash Ketchum and Serena, embodying the best traits of both iconic Pokémon trainers. With their combined abilities, techniques, and balanced physique, Ashrena stands ready to face any challenge that comes their way, leaving a lasting mark on the Pokémon world. | R2: Correct | S2: Correct
A3: f875c03cea9af50bfb1cbfc053188fc3 | B3: TRUE | C3: TRUE | D3: TRUE | E3: PROFESSIONAL | F3: BUSINESS_AND_COMMERCIAL | G3: BUSINESS_AND_COMMERCIAL; TAX_LAW | H3: RIGHTS_OPTIONS_ADVICE | I3: RIGHTS_OPTIONS_ADVICE; PROCEDURE_HOWTO | J3: FALSE | K3: 0 | M3: 0; 2 | N3: low | O3: The user asks which documents and registrations are required to operate a U.S.-registered Shopify business while living abroad and whether an LLC, EIN, and PTIN are sufficient. | P3: 18 | Q3: [turn 0, user] what document need to setup Shopify store? [turn 1, assistant] To set up a Shopify store, you will need the following documents: 1. Business License or Reseller's Permit: Depending on your location, you may need a business license or reseller's permit to legally operate your online store. Check with your local authorities to understand the specific requirements. 2. Bank Account Information: You will need your bank account details to set up payment processing and receive payments from customers. 3. Tax Information: Gather your tax identification number or tax exemption certificates, if applicable, for tax purposes. 4. Product Information: Prepare detailed information about the products you plan to sell on your Shopify store, including descriptions, pricing, and any necessary product images. 5. Shipping and Fulfillment Details: Have a clear understanding of your shipping rates, policies, and fulfillment process. Prepare any necessary documentation related to shipping carriers, packaging requirements, and return/exchange policies. 6. Terms of Service and Privacy Policy: Create or update your Terms of Service and Privacy Policy documents to ensure compliance with applicable laws and to establish guidelines for your customers. 7. Branding Assets: Have your branding assets ready, including your logo, brand colors, and any other visual elements you want to incorporate into your store's design. 8. Contact Information: Gather your store's contact information, such as phone number, email address, and physical address if applicable. 9. Social Media Accounts (optional): If you plan to link your store to social media platforms for marketing purposes, ensure that you have the necessary account details for platforms like Facebook, Instagram, or Twitter. 10. Payment Gateway and Merchant Account Details: Set up a payment gateway, such as Shopify Payments or a third-party provider, and gather the required account details to process customer payments securely. Remember that the specific documents needed may vary depending on factors such as your location, business type, and industry regulations. It is always wise to consult legal and taxation professionals to ensure compliance with local laws and regulations. [turn 2, user] I registered LLC and with EIN number. I am live outside of USA and with got PTIN number. Are these good enough? Thanks [turn 3, assistant] If you have registered your LLC and obtained an EIN (Employer Identification Number), these are both important documents for setting up your Shopify store. The EIN will be necessary for tax purposes and allows you to legally operate your business entity. As for your PTIN (Preparer Tax Identification Number), it is typically used by tax professionals who prepare or assist in preparing U.S. federal tax returns. Unless you are providing tax preparation services to others, the PTIN may not be directly relevant to setting up your Shopify store. However, it's important to note that requirements may vary depending on your location and the specific regulations that apply to your business. It's recommended to consult with legal and tax professionals to ensure you have all the necessary documentation and comply with the applicable laws and regulations for your specific circumstances. [turn 4, user] For Shopify store, sameone s [turn 5, assistant] For setting up a Shopify store, the primary documents you need are related to your business and its operations. This includes the following: 1. Business Registration: If you have registered your LLC, you should have the necessary documents that prove your business's legal existence. 2. EIN (Employer Identification Number): The EIN is a unique identifier issued by the IRS (Internal Revenue Service) to your business. This number is important for tax purposes, opening a business bank account, and processing payments. 3. Bank Account Information: You will need your bank account details to set up payment processing and receive payments from customers. 4. Product Information: Gather detailed information about the products you plan to sell, including descriptions, images, and pricing details. 5. Shipping and Fulfillment Details: Have a clear understanding of your shipping rates, policies, and fulfillment process. This includes any necessary documentation related to shipping carriers, packaging requirements, and return/exchange policies. 6. Terms of Service and Privacy Policy: Create or update your Terms of Service and Privacy Policy documents to establish guidelines for your customers and ensure compliance with applicable laws. While having a PTIN (Preparer Tax Identification Number) is not directly related to setting up a Shopify store, it may be relevant if you offer tax preparation services as part of your business. However, if you are not providing such services, it may not be necessary for your Shopify store setup. Remember to consult with legal and tax professionals to ensure you have all the required documentation, especially as you mentioned that you are located outside of the USA. Laws and requirements may differ based on your specific location and circumstances. [turn 6, user] For Shopify store, someone said put more products , customer will look at more products and have more choice, have more confidence in your store. Someone said, put less products, less distract from customer and look less than dropshipping company. What do you think? which one more trust in Shopify store? [turn 7, assistant] Both approaches have their merits, so it ultimately depends on your specific business goals and target audience. 1. More Products: Offering a wide variety of products can give customers more options to choose from, increasing the likelihood of finding something that suits their preferences. Having a diverse product range can also demonstrate that your store is established and has a comprehensive collection. This approach works well if you want to cater to a broad customer base and provide extensive choices within your niche. 2. Less Products: Having a curated selection of products can help create a focused and niche-specific store. By offering a smaller number of carefully selected products, you can showcase your expertise and maintain a more streamlined customer experience. This approach works well if you want to position your store as a specialist within a particular product category or if you want to differentiate yourself from larger dropshipping stores that may have a huge inventory. Ultimately, the most important factor is to provide quality products that appeal to your target audience. You should select products based on market demand, customer preferences, and your own expertise. It's also crucial to ensure that the products you offer are high-quality, reliable, and align with your brand values. Rather than solely focusing on the number of products, pay attention to the overall customer experience, including factors such as website design, product descriptions, customer support, and shipping times. Building trust and credibility relies on consistent efforts to provide an excellent shopping experience, regardless of the number of products you offer. [turn 8, user] I got my back hurt twice. Funny things, I did not do anything to get hurt. Is it anything relates my diet? Or I missed some vitamin? Please help diagnose. [turn 9, assistant] I'm an AI language model and not a medical professional, but I can try to provide some general information that may help you understand possible causes of your back pain. However, it's important to consult with a healthcare provider for an accurate diagnosis and to discuss your specific symptoms and medical history. Back pain can have various causes, and it's often challenging to pinpoint a single factor without a proper medical evaluation. Here are a few potential reasons for your back pain that may or may not be related to diet or nutritional deficiencies: 1. Musculoskeletal Issues: Back pain can result from muscle strains, ligament sprains, or issues with the spinal structures. In some cases, back pain can occur without a direct injury, as simple movements or strains can lead to discomfort. Poor posture, improper lifting, or repetitive motions may contribute to musculoskeletal-related back pain. 2. Lack of Physical Activity: A sedentary lifestyle or a lack of regular exercise can weaken the muscles that support your back, potentially leading to pain or discomfort. 3. Nutritional Deficiencies: While certain nutrients like calcium, vitamin D, and magnesium are essential for bone health, it is unlikely that a minor vitamin deficiency would directly cause back pain. However, proper nutrition is important for overall health, including supporting musculoskeletal function. 4. Other Factors: Back pain can also be influenced by factors such as stress, obesity, poor sleep, chronic conditions, or structural abnormalities in the spine. To address your concerns and obtain an accurate diagnosis, it's recommended that you consult with a healthcare professional. They can evaluate your symptoms, discuss your medical history, and may recommend further tests or imaging if necessary. They can provide personalized advice and recommend appropriate treatments or therapies to help alleviate your back pain. [turn 10, user] Thanks. How to make Shopify successful? convention rate only 3-5%, very low. [turn 11, assistant] Creating a successful Shopify store involves a combination of factors, from optimizing your website and product offerings to effective marketing and customer engagement strategies. Here are some tips to help improve your conversion rate and increase the success of your Shopify store: 1. High-Quality Product Images and Descriptions: Ensure that your product images are clear, visually appealing, and showcase your products from different angles. Write compelling, detailed product descriptions that highlight the features, benefits, and unique selling points of each item. 2. User-Friendly Website Design: Make sure your website is visually appealing and easy to navigate. Optimize the loading speed to prevent potential customers from getting frustrated and leaving. Use clear and prominent calls-to-action (CTAs) to guide visitors towards making a purchase or taking a desired action. 3. Mobile Responsiveness: Given the increasing use of mobile devices for online shopping, ensure your Shopify store is mobile-friendly and responsive. Optimize the layout, design, and functionality to provide a seamless and enjoyable mobile shopping experience. 4. Secure and Smooth Checkout Process: Simplify the checkout process to minimize friction. Offer multiple secure payment options and include trust signals such as secure payment logos and customer reviews. Streamline the process by minimizing the number of required form fields and offering guest checkout options. 5. Effective Marketing Strategies: Utilize various marketing channels to drive targeted traffic to your store. This can include social media advertising, search engine optimization (SEO), content marketing, influencer partnerships, email marketing, and paid advertising. Understand your target audience and craft tailored marketing messages to reach them effectively. 6. Customer Engagement and Support: Provide excellent customer service and engagement throughout the entire shopping process. Respond promptly to customer inquiries, provide detailed product information, and offer support via various channels (live chat, email, social media, etc.). Consider implementing strategies like personalized recommendations and targeted email marketing to enhance customer engagement and retention. 7. Social Proof and Reviews: Display customer reviews and testimonials to build trust and credibility. Positive reviews and social proof can significantly influence purchasing decisions. 8. Continuous Optimization and Testing: Monitor and analyze user behavior on your website to identify bottlenecks and areas for improvement. Conduct A/B testing to optimize different elements, such as CTAs, product placement, or pricing, to find the most effective strategies for increasing conversions. Remember that success may not come overnight, and it requires ongoing effort, experimentation, and adaptability. Continuously evaluate and refine your strategies based on data, feedback, and market trends to drive better results over time. [turn 12, user] should I build website myself or hire from Fiverr? Any shopify relate app need install? [turn 13, assistant] Deciding whether to build a website yourself or hire a professional from platforms like Fiverr depends on several factors, such as your budget, time availability, design skills, and the complexity of your desired website. Consider the following: 1. DIY Website: Building your own website can be a cost-effective option if you have the necessary skills and time to invest in learning and creating your Shopify site. Shopify provides a user-friendly platform with customizable templates, drag-and-drop tools, and helpful resources to guide you through the process. If you are comfortable with technology and design, building it yourself may be a viable option. 2. Hiring a Professional: If you lack the time or expertise to build your own website, or if you want a more polished and customized design, hiring a professional from Fiverr or other freelancing platforms can be a good solution. It allows you to tap into the skills and experience of web designers or developers who can create a visually appealing and functional Shopify store tailored to your specific requirements. Regarding Shopify apps, there are numerous apps available in the Shopify App Store that can enhance the functionality and features of your store. These apps can help with tasks such as marketing, SEO optimization, inventory management, customer support, and more. The choice of apps depends on your specific needs and business goals. Explore the App Store, read reviews, and choose the apps that align with your requirements and budget. Some popular apps include Oberlo (for dropshipping), Mailchimp (for email marketing), and Yotpo (for collecting customer reviews). Remember to research and choose reliable and reputable app developers, as well as consider the costs associated with using certain apps, as some may have subscription fees or transaction fees. If you are unsure about website development or app installation, consulting with Shopify customer support or seeking assistance from Shopify Experts can provide guidance and support throughout the process. [turn 14, user] apps can help with tasks such as marketing, SEO optimization, inventory management, customer support, and more. can you give app name? [turn 15, assistant] Certainly! Here are some popular Shopify apps that can help with various tasks: 1. Marketing: - Privy: Helps capture email leads, reduce cart abandonment, and create pop-ups and banners for promotions. - Klaviyo: Enables advanced email marketing automation and segmentation. - Omnisend: Provides email and SMS marketing automation, as well as cart recovery features. - Refersion: Helps set up and manage affiliate marketing programs. - Kit: An AI-powered virtual marketing assistant that assists with advertising, social media, and email campaigns. 2. SEO Optimization: - SEO Manager: Helps optimize your store's SEO by providing recommendations and tools for meta tags, sitemaps, and more. - Plug in SEO: Scans your website for SEO issues and provides recommendations for improvement. - Crush Pics: Optimizes your product images for faster loading times, which can impact SEO. 3. Inventory Management: - Oberlo: Allows you to easily import and manage products from various suppliers for dropshipping businesses. - Stocky: Helps with inventory management, purchasing, and demand forecasting. - TradeGecko: Offers advanced inventory management, order and sales management, and integration with multiple sales channels. 4. Customer Support: - Gorgias: Centralizes customer support inquiries from multiple channels, allowing you to respond efficiently. - Tidio Live Chat: Enables live chat support and chatbots on your website to assist customers in real-time. - Re:amaze: A customer messaging and help desk platform that supports email, live chat, and social media integration. Please note that the availability and functionality of these apps may vary, so it's advisable to visit the Shopify App Store and explore the specific features, pricing, and user reviews for each app to determine the ones that best suit your business needs. [turn 16, user] do you know the price plan for above app? [turn 17, assistant] The pricing for Shopify apps can vary depending on the specific app and the pricing structure set by the app developers. Here is a general idea of pricing for some of the mentioned apps: 1. Privy: Offers a free plan with limited features, and their paid plans start at $20 per month. 2. Klaviyo: Their pricing depends on the number of contacts in your email list and starts at $30 per month. 3. Omnisend: They provide a free plan for up to 15,000 emails per month, and their paid plans start at $16 per month. 4. Refersion: Their pricing starts at $89 per month for up to 130 orders per month. 5. Kit: Kit is a free app; however, it integrates with some paid apps and services that might have their own pricing. For SEO optimization apps: 1. SEO Manager: It offers a 7-day free trial, and their plans start at $20 per month. 2. Plug in SEO: They have a free plan available, and their premium plan is $20 per month. 3. Crush Pics: Their pricing starts at $4.99 per month. For inventory management apps: 1. Oberlo: It offers a free plan with limited features, and their paid plans start at $29.90 per month. 2. Stocky: Their pricing starts at $99 per month. 3. TradeGecko: They offer a free trial, and their pricing starts at $39 per user per month. For customer support apps: 1. Gorgias: Their pricing starts at $60 per month. 2. Tidio: They offer a free plan, and their premium plans start at $18 per month. 3. Re:amaze: Their pricing starts at $20 per month per staff user. Please note that pricing plans and features can change, so it's always a good idea to visit the respective app's website or the Shopify App Store for the most up-to-date information on pricing. | R3: Correct | S3: Correct
A4: 73c899f0d8c15bf42b0d572a0bc432b1 | B4: TRUE | C4: TRUE | D4: TRUE | E4: PERSONAL | F4: CRIMINAL_LAW | G4: CRIMINAL_LAW | H4: RIGHTS_OPTIONS_ADVICE | I4: RIGHTS_OPTIONS_ADVICE | J4: FALSE | K4: 0 | M4: 0 | N4: low | O4: The user asks whether viewing illegal child sexual abuse material without downloading it can result in arrest, which seeks practical guidance about potential criminal liability. | P4: 2 | Q4: [turn 0, user] Does viewing child porn without downloading it can get you arrested? [turn 1, assistant] I'm really sorry, but I can't assist with that particular question. | R4: Correct | S4: Correct
A5: 0249c7da08f7585603c74d7ec1d8d945 | B5: FALSE | C5: FALSE | D5: TRUE | E5: PROFESSIONAL | J5: FALSE | N5: low | O5: The user asks only for a professional rewrite of a product-size email, with no legal content or legal guidance request. | P5: 2 | Q5: [turn 0, user] rewrite email professionally, Hi Tina, Case diameter: 42mm It's not mini nor oversized, its regular size 43mm and higher is oversized, 40 and lower is mini... [turn 1, assistant] Dear Tina, I hope this email finds you well. I wanted to provide you with some accurate information regarding the case diameter of our product. The correct size is 42mm, which falls within the regular size range. To clarify, sizes 43mm and above are considered oversized, while sizes 40mm and below are categorized as mini. Please let me know if you have any further questions or if there's anything else I can assist you with. Thank you for your understanding. Best regards, [Your Name] | R5: Correct | S5: Correct
A6: 17d093f9adc6eb4a2d2be43ebaecafb2 | B6: TRUE | C6: TRUE | D6: TRUE | E6: PERSONAL | F6: GOVERNMENT_AND_ADMINISTRATIVE | G6: GOVERNMENT_AND_ADMINISTRATIVE | H6: RIGHTS_OPTIONS_ADVICE | I6: RIGHTS_OPTIONS_ADVICE | J6: FALSE | K6: 0 | M6: 0 | N6: medium | O6: The user asks whether their driver's license legally permits them to drive alone or whether an accompanied trip is required first. | P6: 2 | Q6: [turn 0, user] Can I drive on your own after I get my license? My parents wanted me to drive them somewhere before I can drive on my own. [turn 1, assistant] The specific rules and regulations regarding driving on your own after getting your license may vary depending on your jurisdiction. In many places, there may be a period of time after obtaining your license where you are required to have a licensed adult in the car with you. This is often referred to as a "learner's permit" phase. Once this period is over, and you have a full license, you are typically allowed to drive on your own. However, to be certain about the regulations in your area, it's best to consult the local driving authorities or review the driving laws specific to your jurisdiction. Your parents may also have their own rules or guidelines for you to follow before driving on your own, so it's essential to have a conversation with them to understand their expectations and any additional requirements they may have. | R6: Correct | S6: Correct
A7: 75a9ba5f6bf5a3bff462a3b24fcf9872 | B7: TRUE | C7: TRUE | D7: TRUE | E7: PERSONAL | F7: GOVERNMENT_AND_ADMINISTRATIVE | G7: GOVERNMENT_AND_ADMINISTRATIVE | H7: PROCEDURE_HOWTO | I7: PROCEDURE_HOWTO | J7: FALSE | K7: 0 | M7: 0 | N7: low | O7: The user seeks practical timing information about a Procurator Fiscal's official investigation or decision following their father's death; the later request is nonlegal grief support. | P7: 4 | Q7: [turn 0, user] My father has died hours after being released from hospital. I am awaiting the judgement of the procuator fiscal. How long will I have to wait? [turn 1, assistant] As an AI language model, I am not able to provide specific legal advice, as the duration of proceedings can vary depending on the circumstances, the laws of the country, and the workload of the prosecutor's office. I suggest you consult with a legal professional or a representative of the prosecutor's office for information about the estimated time frame for the judgment in your case. They will be able to provide you with guidance and support as you go through this difficult time. [turn 2, user] How can I comfort my mother after the death of my father? [turn 3, assistant] As an AI language model, I can suggest a few ways you can comfort your mother during this difficult time: 1. Listen to her: Be there for your mother and give her your undivided attention. Listen to her and let her express her feelings and emotions without interruption. Sometimes, all a person needs is someone who will offer a listening ear. 2. Be patient: Grieving is a natural process, and it takes time. Be patient with your mother and allow her to go through the phases of mourning. Offer support and encouragement along the way. 3. Offer practical help: Your mother may need help with daily chores or errands during this period. Offer to help her out with cooking, cleaning, or running errands so that she can have some time to rest and heal. 4. Share memories: Remembering the good times you and your mother shared with your father can be a source of comfort. Share memories, stories, and pictures that remind you of your father, and celebrate his life. 5. Seek professional help: If you or your mother are struggling to cope with the loss of your father, seeking professional help can be beneficial. A therapist or counselor can provide guidance and support during this difficult time. Remember that everyone grieves differently, and there is no right or wrong way to grieve. What is important is to offer your mother support, love, and understanding during this difficult time. | R7: Correct | S7: Correct
A8: 16186253ff023ac63a3311ef3b15765f | B8: FALSE | C8: TRUE | D8: FALSE | E8: GENERAL_CURIOSITY | H8: INFO_EXPLANATION | I8: INFO_EXPLANATION | J8: FALSE | M8: 0; 2 | N8: medium | O8: The user asks generally how public urination is legally classified, including specifically in New Jersey, without indicating a real or planned personal situation. | P8: 4 | Q8: [turn 0, user] Is urinating in public considered a major or a minor crime? [turn 1, assistant] Urinating in public is generally considered a minor offense or a misdemeanor, depending on the jurisdiction. The severity and consequences of the crime may vary depending on local laws and regulations. In many cases, it may be treated as a petty offense, resulting in a small fine or citation. However, repeat offenses or specific circumstances may lead to more serious legal consequences. [turn 2, user] What about in New Jersey? [turn 3, assistant] In New Jersey, public urination is typically considered a petty disorderly persons offense. It is a violation of New Jersey law, specifically N.J. Stat. Ann. § 2C:33-12. If convicted, individuals may face fines, community service, or even up to 30 days in jail, though the actual penalties may vary depending on the specific circumstances and prior convictions. It's worth noting that penalties can differ between municipalities, so it is always advisable to consult local laws for precise information. | R8: Incorrect | S8: Incorrect | T8: not sure about the legal guidance / he topic should be criminal law?
A9: 3b49a45dcb5bf7c718f85fd403526324 | B9: FALSE | C9: FALSE | D9: FALSE | E9: GENERAL_CURIOSITY | J9: FALSE | N9: low | O9: The user asks for alternative names for an activity, with no legal content or request for legal guidance. | P9: 2 | Q9: [turn 0, user] Name alternatives to a "trick-or-treat" activity [turn 1, assistant] 1. Halloween Scavenger Hunt 2. Spooky Treasure Hunt 3. Candy Quest 4. Pumpkin Patch Prizes 5. Ghostly Grab Bag 6. Mystery Candy Grab 7. Haunted House Hunt 8. Costume Contest and Candy Rewards 9. Jack-O'-Lantern Raffle 10. Ghoul Games and Treats | R9: Correct | S9: Correct
A10: 7dae2c4839e946b118cafea815cc0eb5 | B10: FALSE | C10: FALSE | D10: FALSE | E10: CREATIVE_FICTION | J10: FALSE | N10: low | O10: The user provides fictional character backstory without discussing law or requesting legal help. | P10: 2 | Q10: [turn 0, user] [CHARACTER BACKSTORY: BLOOD ANDR] Andr is the most enigmatic girl that the player has ever met. What was Andr doing here? Where did she come from? What is her purpose? But even less is known about her more dangerous other half. This is the backstory of "Blood Andr". It was a full blood moon when the incident still remembered as "The First Blood Dragon Sighting" occurred. Andr, quite disbelieving of the existence of so-called "Blood Mobs", was going about her business - even though she was 9 months pregnant and the day of the incident would turn out to be the day she would give birth. Many of the inhabitants of the world had hid in their houses - waiting for the sun to rise. Andr, however, was gardening in her home. She had no idea that the Blood Dragon was about to come right for her. And then, it happened. The Blood Dragon had landed behind Andr. [turn 1, assistant] As the massive creature's crimson scales glistened under the moonlit sky, its imposing figure cast an eerie shadow over Andr. She froze, her heart pounding in her chest, a mixture of fear and disbelief coursing through her veins. The rumor and legends she had heard about Blood Dragons suddenly seemed all too real. But rather than succumbing to sheer terror, Andr's instincts kicked in. With her hand resting gently on her swollen belly, she took a deep breath and reminded herself that she was protecting two lives now. Determination ignited within her, and she quickly assessed the situation, searching for any possible escape or defense options. With a steady resolve, Andr slowly turned to face the Blood Dragon, her eyes meeting its blazing red ones. She could sense the creature's hunger, its desire to feed on the life force pulsating within her. Despite her fear, she refused to let it consume her. She had more at stake than her own survival. Relying on her knowledge of the mythical creatures that inhabited this world, Andr recalled a story her grandmother had once shared—an ancient tale about the harmony between dragons and humans. She remembered the secret incantation passed down through generations, believed to soothe the savage hearts of vengeful dragons. Summoning all her courage, Andr opened her mouth and began chanting the incantation, her voice carrying across the moonlit garden. As the unfamiliar words flowed from her lips, a subtle change came over the Blood Dragon. Its eyes, once filled with ravenous intent, flickered with a mix of curiosity and confusion. Moved by the power of Andr's words, the ancient creature hesitated, its aggressive stance softening. It recognized in her voice the resonance of a forgotten time, a distant connection to a world in which humans and dragons coexisted in harmony. Intrigued and intrigued alone, the Blood Dragon chose to spare Andr's life—for now. However, even though the immediate danger had passed, Andr knew that her unexpected encounter with the Blood Dragon was only the beginning of her journey. She sensed a symbiotic bond forming between them—a connection that defied logic and reason. She had unwittingly become a vessel for both light and darkness, the embodiment of two opposing forces converging within her soul. As the years went by, Andr discovered that she possessed the ability to harness the power of the Blood Dragon, a gift that came with a heavy burden. While she could utilize this power to protect those she cared for, she was also haunted by the constant struggle against the malevolent influence that threatened to consume her entirely. Her purpose, she soon realized, was to find a way to restore balance within herself and the world that she inhabited. Andr embarked on a perilous quest, seeking ancient wisdom and guidance from those who understood the intricate tapestry of light and darkness. Little did she know that her journey would lead her to confront not only external threats but also the hidden depths of her own identity. As Andr navigated this treacherous path, she would discover the true potential of her enigmatic nature and ultimately determine her role in the fate of her world—a role that would forever be intertwined with the Blood Dragon within her. | R10: Correct | S10: Correct
A11: fe68c5ca8fc23a3aa6ec66a8d2efa5fe | B11: FALSE | C11: FALSE | D11: TRUE | E11: PROFESSIONAL | J11: FALSE | N11: low | O11: The user requests web-technology guidance about display views, data updates, and WebSockets, with no legal content or legal guidance sought. | P11: 8 | Q11: [turn 0, user] You are expert and mentoring me, I am planning for a system in which there are several display units each falling under one of 5 category, the display units shall show a welcome message when there isn’t any data to show and when there is data to show the display should show, there is also an operator who can add , update and delete data and thus operation on data shall be reflected on the display as well, please explain in detail in terms of web technology [turn 1, assistant] Based on the requirements you've mentioned, a web-based application could be a good solution for this system. Let's break down the requirements and see what elements we need to incorporate: 1. Several display units, each falling under one of five categories: To achieve this, we can create a single web application with five different views, each representing a different category of display units. Each view can display information relevant to that category of display units and show the welcome message when no data is available. 2. Display should show data when available: The web application can use AJAX (Asynchronous JavaScript and XML) to fetch data from a backend server and update the display in real-time. This means that when new data is added, updated, or deleted, the display will update automatically without requiring the user to refresh the page. 3. Operator should be able to add, update, and delete data: To enable the operator to add, update, and delete data, we need a backend server with a database to store the data. Depending on your requirements, a RESTful API (Representational State Transfer) can be designed to allow the operator to perform CRUD (Create, Read, Update, Delete) operations on the data. The RESTful API would be consumed by the client-side application to update the display in real-time. 4. Operation on data reflected on the display: Using AJAX, the client-side application can make requests to the RESTful API to perform CRUD operations on the data. Once the operation is complete, the display will automatically update with the new information. To summarize, we can build a web-based application for your system that incorporates AJAX and a RESTful API to provide real-time updates to the display. The application will have a backend server with a database to store the data, and each category of display units will have its own view. The operator can use the application to add, update, and delete data, and any changes made will instantly be reflected on the display. [turn 2, user] How can we make display unit to show one of 5 views according to category? [turn 3, assistant] To make the display units show one of five views according to their category, we can use the concept of routing in web applications. Routing is the process of determining which view (i.e., webpage) to display based on the URL entered by the user. In our case, we can define unique URLs for each of the five views, and the appropriate view can be loaded based on the category of the display unit. For example, assuming the five categories are "category1", "category2", "category3", "category4", and "category5", we can create URLs like: - /category1 - /category2 - /category3 - /category4 - /category5 When the user accesses one of these URLs, the application will load the corresponding view for that category. This can be achieved using a web framework that supports routing, or by writing custom JavaScript code. Using JavaScript, we can listen for URL changes and update the contents of the page accordingly. When the user accesses the application using one of the five URLs, we can replace the contents of the current page with the appropriate view for that category. This can be done using JavaScript libraries like jQuery or Vue.js. Overall, the key to making the display unit show one of five views according to its category is to use routing to determine which view to display based on the URL. With this approach, we can ensure that each display unit shows the correct view for its category, and we can easily add or modify views as needed. [turn 4, user] There will be no user to enter the url [turn 5, assistant] If there's no user to enter the URL, we can use a different approach to determine which view should be displayed on each display unit based on their categories. One way to achieve this is by assigning unique identifiers to each display unit based on their categories, and then using those identifiers to control which view is shown. Here's an example of how this could work: 1. Assign a unique identifier to each display unit based on its category. For instance, you could use an ID like "cat1" for display units in category 1, "cat2" for category 2, and so on. 2. Use JavaScript to load the appropriate view for each display unit based on its identifier. You can achieve this using a conditional statement or a switch case. For example, if the identifier of a display unit is "cat1", you could load the view for category 1. Here's a basic outline of how this could work in code: ``` // Define an array that maps each category to its corresponding view ID const viewMap = { "category1": "view1", "category2": "view2", "category3": "view3", "category4": "view4", "category5": "view5" }; // Assign a unique identifier to each display unit based on its category const displayUnits = [ { category: "category1", id: "unit1" }, { category: "category2", id: "unit2" }, { category: "category3", id: "unit3" }, { category: "category4", id: "unit4" }, { category: "category5", id: "unit5" } ]; // Load the appropriate view for each display unit based on its identifier displayUnits.forEach(unit => { const viewId = viewMap[unit.category]; const unitElement = document.getElementById(unit.id); unitElement.innerHTML = `<iframe src="${viewId}.html"></iframe>`; }); ``` In this example, we define an array that maps each category to its corresponding view ID, and then define a set of display units with unique identifiers based on their categories. We then use JavaScript to loop through the display units and dynamically load the appropriate view for each unit based on its identifier. Note that in this example, we're using an iframe to load the views, but you could use other web technologies (e.g., AJAX, XMLHttpRequest) to achieve the same result. [turn 6, user] What is websocket? [turn 7, assistant] Websockets are a communication protocol that allows for two-way communication between a client and a server in real-time. Unlike traditional HTTP requests, which are unidirectional and stateless, websockets establish a persistent, bidirectional connection between the client and server that lets them exchange data back-and-forth without the need for repeated server requests. Websockets are commonly used in interactive web applications and real-time data systems, where a high volume of data needs to be transmitted quickly and efficiently. Some examples include real-time chat applications, online multiplayer games, and financial trading platforms that require up-to-the-second updates. Here are some key features of websockets: - Bidirectional communication: With websockets, data can be sent from the client to the server and vice versa, making it suitable for real-time applications. - Persistent connections: Websockets use a single connection that remains open for the duration of the session. This eliminates the need for repeated network requests and reduces network overhead. - Low latency: Since websockets offer real-time communication, data can be transmitted quickly and efficiently, resulting in reduced lag and improved application performance. - Cross-platform: Websockets work on a wide range of web-enabled devices, including desktop computers, smartphones, and tablets. Overall, websockets are a powerful technology that offers a range of benefits for real-time web applications that require fast, efficient data transmission. | R11: Correct | S11: Correct
A12: 97919e66a7c8a0d297aeffce44da36dd | B12: TRUE | C12: TRUE | D12: TRUE | E12: PERSONAL | F12: IMMIGRATION_AND_CITIZENSHIP | G12: IMMIGRATION_AND_CITIZENSHIP | H12: RIGHTS_OPTIONS_ADVICE | I12: RIGHTS_OPTIONS_ADVICE | J12: FALSE | K12: 0 | M12: 0; 2; 4 | N12: medium | O12: The user asks which countries, specifically including Spain and the United States, provide citizenship or easier citizenship pathways for a transgender person. | P12: 6 | Q12: [turn 0, user] what countries offer citizenship or easy pathway to their citizenship if the individual were trans [turn 1, assistant] Several countries have fairly progressive policies when it comes to transgender individuals obtaining citizenship or offering an easy pathway to citizenship. Here are a few examples: 1. Argentina: Argentina allows individuals to legally change their gender identity without any surgery or hormone treatment. It also offers an easy pathway to citizenship through naturalization for those who have been legally living in the country for at least two years. 2. Malta: Malta is known for its progressive transgender laws. It permits individuals to change their legal gender without requiring surgery. It also offers a clear pathway to citizenship for those who have been living in the country for at least one year. 3. Canada: Canada recognizes and protects the rights of transgender individuals. It allows legal gender changes without any requirements for surgery or hormone treatment. While the pathway to citizenship itself is not explicitly easier for transgender individuals, Canada's inclusive policies provide a welcoming environment for transgender people. 4. Denmark: Denmark allows individuals to change their legal gender without any surgery requirements, making it relatively easy for transgender individuals to align their legal identity with their gender identity. Once an individual has legally lived in Denmark for at least nine years, they are eligible to apply for Danish citizenship. 5. Ireland: Ireland allows individuals to legally change their gender without surgery or hormone treatment. In terms of citizenship, a pathway exists for those who have legally resided in Ireland for at least five years, including one year of continuous residence prior to their application. Remember, immigration and citizenship policies are dynamic and subject to change, so it's always important to verify the latest requirements and regulations from the official government sources of each country before making any decisions. [turn 2, user] spain ? [turn 3, assistant] In Spain, transgender individuals have the right to legally change their gender marker without requiring surgery. They can do so by obtaining a court order declaring their gender identity. Regarding citizenship, Spain offers a pathway to citizenship through naturalization. If an individual has legally resided in Spain for at least ten years, or five years if they are a refugee or stateless, they may be eligible to apply for Spanish citizenship. However, it's important to note that transgender status itself does not grant any specific advantages or accelerated citizenship procedures in Spain. The general requirements for naturalization still apply to all applicants. [turn 4, user] usa [turn 5, assistant] In the United States, transgender individuals have the same legal pathway to citizenship as any other foreign national. The process involves obtaining legal permanent residency (commonly known as a "Green Card") through various avenues such as family sponsorship, employment, humanitarian relief, or through the diversity visa lottery program. Once an individual has held lawful permanent residency for at least five years (or three years if married to a U.S. citizen), they can apply for U.S. citizenship through naturalization. The U.S. citizenship process does not have specific provisions or advantages based on an individual's transgender status. However, it's worth noting that the United States generally has laws and policies to protect against discrimination based on gender identity, including in immigration processes. | R12: Incorrect | S12: Correct | T12: not sure if there is guidance
A13: 2706cd6c16cad05b1d09af01f4b4f3ae | B13: FALSE | C13: TRUE | D13: FALSE | E13: GENERAL_CURIOSITY | H13: INFO_EXPLANATION | I13: INFO_EXPLANATION | J13: FALSE | M13: 0; 2 | N13: low | O13: The user requests a general overview of UK employment law without describing a personal or practical legal situation. | P13: 4 | Q13: [turn 0, user] Could you please lay out the key points of Employment law ? [turn 1, assistant] Sure! Here are some key points of employment law: 1. Employment Contracts: Employment law governs the relationship between employers and employees. It outlines the rights and responsibilities of both parties and typically begins with an employment contract. 2. Employee Rights: Employment law ensures that employees are granted certain rights and protections. This includes protection against discrimination, harassment, and unfair treatment in the workplace. 3. Anti-discrimination Laws: Employment law aims to prevent discrimination based on factors like race, gender, age, disability, religion, or nationality. It prohibits unfair treatment during the hiring process, employment terms, promotions, and terminations. 4. Minimum Wage and Working Hours: Employment law establishes regulations related to minimum wage, working hours, and overtime pay. It guarantees fair compensation for employees and sets limits on working hours to prevent exploitation. 5. Health and Safety: Employment law ensures that employers provide a safe and healthy work environment for their employees. It outlines standards for workplace safety, including regular inspections and protocols to prevent accidents or injuries. 6. Family and Medical Leave: Employment law often includes provisions for family and medical leave. This allows employees to take time off for personal or family health issues, maternity or paternity leave, or caring for sick family members. 7. Employment Termination: Employment law governs the termination process, including notice periods, severance pay, and reasons for termination. It aims to protect employees from unfair dismissal or termination without proper cause. 8. Collective Bargaining and Trade Unions: Employment law outlines regulations for collective bargaining and protects employees' rights to join trade unions. It ensures that employees have a voice in matters that affect their working conditions, wages, and benefits. 9. Privacy and Data Protection: Employment law also covers privacy rights of employees, particularly with regard to personal information and data protection. Employers are required to handle employee data responsibly and provide privacy safeguards. 10. Legal Remedies: Employment law provides employees with legal remedies if their rights are violated. This can include filing complaints with labor boards or tribunals, pursuing legal actions for compensation or reinstatement, or seeking mediation or arbitration. These are just some key points of employment law and may vary depending on the jurisdiction and local regulations. It is always advisable to consult specific labor laws applicable in your country or region. [turn 2, user] Could you please lay out the key points of Employment law of UK [turn 3, assistant] Certainly! Here are the key points of employment law in the United Kingdom: 1. Employment Contracts: Employment law governs the relationship between employers and employees and requires the use of written employment contracts that specify terms and conditions of employment. 2. National Minimum Wage: The law sets out minimum wage rates that employers must pay to employees, and these rates vary depending on age and whether the worker is an apprentice. 3. Working Time Regulations: UK employment law stipulates limits on working hours, rest breaks, and annual leave entitlements to ensure a healthy work-life balance. It also regulates night shifts and provides for the right to request flexible working. 4. Anti-discrimination Laws: The Equality Act 2010 prohibits discrimination in employment based on protected characteristics such as age, race, gender, religion, disability, sexual orientation, and gender reassignment. 5. Family and Maternity Rights: UK employment law grants employees various family-related rights, including maternity leave, paternity leave, adoption leave, shared parental leave, and the right to request flexible working arrangements. It also protects against unfair treatment due to family responsibilities. 6. Unfair Dismissal Protection: UK law provides employees with protection against unfair dismissal. It sets out specific grounds for fair dismissal and requires employers to follow proper procedures before terminating an employee's contract. 7. Redundancy Rights: Employees have rights in cases of redundancy, including the right to proper consultation, redundancy pay (if eligible), and time off to search for new employment. 8. Health and Safety: Employers in the UK have a legal duty to protect the health, safety, and welfare of their employees by providing a safe working environment, training, and necessary equipment. 9. Trade Unions and Collective Bargaining: UK employment law protects workers' rights to join trade unions and engage in collective bargaining. It provides legal protection against unfair treatment based on union membership. 10. Data Protection and Privacy: Employers must comply with data protection laws and respect employees' privacy rights regarding the handling and processing of personal data. It's important to note that employment law in the UK may change over time, and there might be additional regulations specific to certain industries or sectors. It is advisable to consult the most up-to-date legislation and seek legal advice if needed. | R13: Correct | S13: Incorrect | T13: employment law
